Process Process-2:
Traceback (most recent call last):
  File "C:\Users\johnolafenwa\Documents\AI\DeepStack\intelligencelayer\shared\face.py", line 186, in face
    det = detector.predict(img, 0.55)
  File "C:\Users\johnolafenwa\Documents\AI\DeepStack\intelligencelayer\shared\.\process.py", line 47, in predict
    img0 = Image.open(img_path).convert("RGB")
  File "C://Users//johnolafenwa//Documents///AI//DeepStack\windows_packages\PIL\Image.py", line 2891, in open
    fp = builtins.open(filename, "rb")
FileNotFoundError: [Errno 2] No such file or directory: 'C:\\Users\\JOHNOL~1\\AppData\\Local\\Temp\\DeepStack\\d4dc827d-27b6-43e4-a256-0e527ca9d232'

During handling of the above exception, another exception occurred:

Traceback (most recent call last):
  File "D:\obj\windows-release\37amd64_Release\msi_python\zip_amd64\process.py", line 297, in _bootstrap
  File "D:\obj\windows-release\37amd64_Release\msi_python\zip_amd64\process.py", line 99, in run
  File "C:\Users\johnolafenwa\Documents\AI\DeepStack\intelligencelayer\shared\face.py", line 253, in face
    except UnidentifiedImageError:
NameError: name 'UnidentifiedImageError' is not defined
